Python 3.6.2 (v3.6.2:5fd33b5926, Jul 16 2017, 20:11:06) 
[GCC 4.2.1 (Apple Inc. build 5666) (dot 3)] on darwin
Type "copyright", "credits" or "license()" for more information.
>>> 
============== RESTART: /Users/thomas_petty24/Documents/MD2.py ==============
>>> 
============== RESTART: /Users/thomas_petty24/Documents/MD2.py ==============
c99bf0b296192db67cf08c0b384b6916
>>> 
============== RESTART: /Users/thomas_petty24/Documents/MD2.py ==============
8ea4ff9ecc36b4bf892f3dd5356cb795
>>> 
============== RESTART: /Users/thomas_petty24/Documents/MD2.py ==============
dc5b695e2c0de57e3aa61c2946a1a8e2
>>> 
===== RESTART: /Users/thomas_petty24/Downloads/USER1/_System/_Core/OS.py =====
j
u
p

=============================== RESTART: Shell ===============================
>>> 
 RESTART: /Users/thomas_petty24/Downloads/USER1/_System/_Core/Emulator/G1/OS.py 
09
04
/Users/thomas_petty24/Downloads/USER1/_System/_Core/Emulator/G1/
Exception in Tkinter callback
Traceback (most recent call last):
  File "/Library/Frameworks/Python.framework/Versions/3.6/lib/python3.6/tkinter/__init__.py", line 1699, in __call__
    return self.func(*args)
  File "/Users/thomas_petty24/Downloads/USER1/_System/_Core/Emulator/G1/Coconet.py", line 39, in search
    f = urllib.request.urlopen(hbox.get())
  File "/Library/Frameworks/Python.framework/Versions/3.6/lib/python3.6/urllib/request.py", line 223, in urlopen
    return opener.open(url, data, timeout)
  File "/Library/Frameworks/Python.framework/Versions/3.6/lib/python3.6/urllib/request.py", line 524, in open
    req = meth(req)
  File "/Library/Frameworks/Python.framework/Versions/3.6/lib/python3.6/urllib/request.py", line 1241, in do_request_
    raise URLError('no host given')
urllib.error.URLError: <urlopen error no host given>
q
k
BackSpace
h
e
l
l
o
Return
Exception in Tkinter callback
Traceback (most recent call last):
  File "/Library/Frameworks/Python.framework/Versions/3.6/lib/python3.6/tkinter/__init__.py", line 1699, in __call__
    return self.func(*args)
  File "/Users/thomas_petty24/Downloads/USER1/_System/_Core/Emulator/G1/OS.py", line 30, in openeg
    eg()
  File "/Users/thomas_petty24/Downloads/USER1/_System/_Core/Emulator/G1/EG1.py", line 107, in eg
    c.pack()
  File "/Library/Frameworks/Python.framework/Versions/3.6/lib/python3.6/tkinter/__init__.py", line 2137, in pack_configure
    + self._options(cnf, kw))
_tkinter.TclError: can't invoke "pack" command:  application has been destroyed
left
left
False
False
False
False
False
False
False
False
False
False
>>> 
===== RESTART: /Users/thomas_petty24/Downloads/USER1/_System/_Core/OS.py =====
h

=============================== RESTART: Shell ===============================
>>> 
 RESTART: /Users/thomas_petty24/Downloads/USER1/_System/_Core/Emulator/G0/OS.py 
Traceback (most recent call last):
  File "/Users/thomas_petty24/Downloads/USER1/_System/_Core/Emulator/G0/OS.py", line 3, in <module>
    os.chdir('Emulator/G0')
FileNotFoundError: [Errno 2] No such file or directory: 'Emulator/G0'
>>> 
===== RESTART: /Users/thomas_petty24/Downloads/USER1/_System/_Core/OS.py =====
s
t
a
r
t

=============================== RESTART: Shell ===============================
>>> 
 RESTART: /Users/thomas_petty24/Downloads/USER1/_System/_Core/Emulator/G2/OS.py 
GORILLA OS 2.0 PROFESSIONAL - BUILD 153
Booting...
Creating System Files...
Checking System Files...
Getting System Files...
Importing Modules and Applications... 0%
Importing Modules and Applications... 40%
Importing Modules and Applications... 70%
Importing Modules and Applications... 100%
Getting Data...
Running Setup Functions...
Defining Setup Functions...
Manual Loaded? NO
Manual Loaded? DONE
Extracting Data Files...
Extracting Data Files...
['0']
Extracting Data Files...
Loading Graphics...
Loading Graphics...
Extracting Data Files...
Loading Graphics...
Loading Graphics...
Updating Graphics...
Loading Binding Template..
Getting Local Data..
Extracting Data Files...
Checking Files...
Checking Files...
Checking Files...
Checking Files...
Checking Files...
Checking Files...
Checking Files...
Checking Files...
Checking Files...
Checking Files...
Checking Files...
Checking Files...
Checking Files...
Checking Files...
Checking Files...
Checking Files...
Checking Files...
Checking Files...
Checking Files...
Checking Files...
Checking Files...
Checking Files...
Checking Files...
Checking Files...
Checking Files...
Checking Files...
Checking Files...
Checking Files...
Checking Files...
Checking Files...
Checking Files...
Checking Files...
Checking Files...
Checking Files...
Checking Files...
Checking Files...
Checking Files...
Checking Files...
Checking Files...
Checking Files...
Checking Files...
Checking Files...
Checking Files...
Creating Graphics...
Extracting Data...
Running Files...
Updating Graphics...
Updating Graphics...
Updating Graphics...
Extracting Important Data...
Extracting Important Data...
Reading Important Data...
Reading Important Data...
Reading Important Data...
Loading Terms...
Extracting Important Data...
Extracting Important Data...
Extracting Important Data...
Opening Login...
Creating Graphics...
Creating Graphics...
Updating Graphics...
Updating Graphics...
Loading Functions...
Packing Functions...
Finishing...
Empty ('')
 Empty ('')
 Empty ('')
 Empty ('')
 Empty ('')
'' Empty

invalid syntax (<string>, line 1)

 RESTART: /Users/thomas_petty24/Downloads/USER1/_System/_Core/Emulator/G2/OS.py 
GORILLA OS 2.0 PROFESSIONAL - BUILD 153
Booting...
Creating System Files...
Checking System Files...
Getting System Files...
Importing Modules and Applications... 0%
Importing Modules and Applications... 40%
Importing Modules and Applications... 70%
Importing Modules and Applications... 100%
Getting Data...
Running Setup Functions...
Defining Setup Functions...
Manual Loaded? NO
Manual Loaded? DONE
Extracting Data Files...
Extracting Data Files...
['0']
Extracting Data Files...
Loading Graphics...
Loading Graphics...
Extracting Data Files...
Loading Graphics...
Loading Graphics...
Updating Graphics...
Loading Binding Template..
Getting Local Data..
Extracting Data Files...
Checking Files...
Checking Files...
Checking Files...
Checking Files...
Checking Files...
Checking Files...
Checking Files...
Checking Files...
Checking Files...
Checking Files...
Checking Files...
Checking Files...
Checking Files...
Checking Files...
Checking Files...
Checking Files...
Checking Files...
Checking Files...
Checking Files...
Checking Files...
Checking Files...
Checking Files...
Checking Files...
Checking Files...
Checking Files...
Checking Files...
Checking Files...
Checking Files...
Checking Files...
Checking Files...
Checking Files...
Creating Graphics...
Extracting Data...
Running Files...
Updating Graphics...
Updating Graphics...
Updating Graphics...
Extracting Important Data...
Extracting Important Data...
Reading Important Data...
Reading Important Data...
Reading Important Data...
Loading Terms...
Extracting Important Data...
Extracting Important Data...
Extracting Important Data...
Opening Login...
Creating Graphics...
Creating Graphics...
Updating Graphics...
Updating Graphics...
Loading Functions...
Packing Functions...
Finishing...
Empty ('')
 Empty ('')
 Empty ('')
 Empty ('')
 Empty ('')
'' Empty

invalid syntax (<string>, line 1)
Exception in Tkinter callback
Traceback (most recent call last):
  File "/Users/thomas_petty24/Downloads/USER1/_System/_Core/Emulator/G2/OS.py", line 307, in sets
    h = b[1] #set to b[1] once background image is created
IndexError: tuple index out of range

During handling of the above exception, another exception occurred:

Traceback (most recent call last):
  File "/Library/Frameworks/Python.framework/Versions/3.6/lib/python3.6/tkinter/__init__.py", line 1699, in __call__
    return self.func(*args)
  File "/Users/thomas_petty24/Downloads/USER1/_System/_Core/Emulator/G2/OS.py", line 319, in sets
    current = f[0]
IndexError: tuple index out of range
Exception in Tkinter callback
Traceback (most recent call last):
  File "/Users/thomas_petty24/Downloads/USER1/_System/_Core/Emulator/G2/OS.py", line 307, in sets
    h = b[1] #set to b[1] once background image is created
IndexError: tuple index out of range

During handling of the above exception, another exception occurred:

Traceback (most recent call last):
  File "/Library/Frameworks/Python.framework/Versions/3.6/lib/python3.6/tkinter/__init__.py", line 1699, in __call__
    return self.func(*args)
  File "/Users/thomas_petty24/Downloads/USER1/_System/_Core/Emulator/G2/OS.py", line 319, in sets
    current = f[0]
IndexError: tuple index out of range
Exception in Tkinter callback
Traceback (most recent call last):
  File "/Users/thomas_petty24/Downloads/USER1/_System/_Core/Emulator/G2/OS.py", line 307, in sets
    h = b[1] #set to b[1] once background image is created
IndexError: tuple index out of range

During handling of the above exception, another exception occurred:

Traceback (most recent call last):
  File "/Library/Frameworks/Python.framework/Versions/3.6/lib/python3.6/tkinter/__init__.py", line 1699, in __call__
    return self.func(*args)
  File "/Users/thomas_petty24/Downloads/USER1/_System/_Core/Emulator/G2/OS.py", line 319, in sets
    current = f[0]
IndexError: tuple index out of range
Eee
HEY
HEY2
HEY3
Exception in Tkinter callback
Traceback (most recent call last):
  File "/Library/Frameworks/Python.framework/Versions/3.6/lib/python3.6/tkinter/__init__.py", line 1699, in __call__
    return self.func(*args)
  File "/Users/thomas_petty24/Downloads/USER1/_System/_Core/Emulator/G2/Coconet.gr", line 155, in render
    starts = len(items)
UnboundLocalError: local variable 'items' referenced before assignment
Exception in Tkinter callback
Traceback (most recent call last):
  File "/Library/Frameworks/Python.framework/Versions/3.6/lib/python3.6/tkinter/__init__.py", line 1699, in __call__
    return self.func(*args)
  File "/Users/thomas_petty24/Downloads/USER1/_System/_Core/Emulator/G2/OS.py", line 3529, in bf
    gorilla1()
  File "/Users/thomas_petty24/Downloads/USER1/_System/_Core/Emulator/G2/GORILLA1MODE.py", line 1373, in gorilla1
    rmenu.add_command(label='Print...', command=printer)
NameError: name 'printer' is not defined
Exception in Tkinter callback
Traceback (most recent call last):
  File "/Users/thomas_petty24/Downloads/USER1/_System/_Core/Emulator/G2/OS.py", line 307, in sets
    h = b[1] #set to b[1] once background image is created
IndexError: tuple index out of range

During handling of the above exception, another exception occurred:

Traceback (most recent call last):
  File "/Library/Frameworks/Python.framework/Versions/3.6/lib/python3.6/tkinter/__init__.py", line 1699, in __call__
    return self.func(*args)
  File "/Users/thomas_petty24/Downloads/USER1/_System/_Core/Emulator/G2/OS.py", line 319, in sets
    current = f[0]
IndexError: tuple index out of range
2
OUCH!
Exception in Tkinter callback
Traceback (most recent call last):
  File "/Library/Frameworks/Python.framework/Versions/3.6/lib/python3.6/tkinter/__init__.py", line 1699, in __call__
    return self.func(*args)
  File "/Users/thomas_petty24/Downloads/USER1/_System/_Core/Emulator/G2/Fireball.gr", line 116, in startup
    loop(s.get())
  File "/Users/thomas_petty24/Downloads/USER1/_System/_Core/Emulator/G2/Fireball.gr", line 52, in loop
    c.move(fire, no1, no2)
  File "/Library/Frameworks/Python.framework/Versions/3.6/lib/python3.6/tkinter/__init__.py", line 2585, in move
    self.tk.call((self._w, 'move') + args)
_tkinter.TclError: invalid command name ".!canvas"
>>> Exception in Tkinter callback
Traceback (most recent call last):
  File "/Library/Frameworks/Python.framework/Versions/3.6/lib/python3.6/idlelib/run.py", line 137, in main
    seq, request = rpc.request_queue.get(block=True, timeout=0.05)
  File "/Library/Frameworks/Python.framework/Versions/3.6/lib/python3.6/queue.py", line 172, in get
    raise Empty
queue.Empty

During handling of the above exception, another exception occurred:

Traceback (most recent call last):
  File "/Library/Frameworks/Python.framework/Versions/3.6/lib/python3.6/tkinter/__init__.py", line 1699, in __call__
    return self.func(*args)
  File "/Users/thomas_petty24/Downloads/USER1/_System/_Core/Emulator/G2/OS.py", line 3529, in bf
    gorilla1()
  File "/Users/thomas_petty24/Downloads/USER1/_System/_Core/Emulator/G2/GORILLA1MODE.py", line 1373, in gorilla1
    rmenu.add_command(label='Print...', command=printer)
NameError: name 'printer' is not defined
Exception in Tkinter callback
Traceback (most recent call last):
  File "/Library/Frameworks/Python.framework/Versions/3.6/lib/python3.6/idlelib/run.py", line 137, in main
    seq, request = rpc.request_queue.get(block=True, timeout=0.05)
  File "/Library/Frameworks/Python.framework/Versions/3.6/lib/python3.6/queue.py", line 172, in get
    raise Empty
queue.Empty

During handling of the above exception, another exception occurred:

Traceback (most recent call last):
  File "/Library/Frameworks/Python.framework/Versions/3.6/lib/python3.6/tkinter/__init__.py", line 1699, in __call__
    return self.func(*args)
  File "/Users/thomas_petty24/Downloads/USER1/_System/_Core/Emulator/G2/EG1.gr", line 1405, in mousep
    mousetext.delete(0.0, END)
  File "/Library/Frameworks/Python.framework/Versions/3.6/lib/python3.6/tkinter/__init__.py", line 3133, in delete
    self.tk.call(self._w, 'delete', index1, index2)
_tkinter.TclError: invalid command name ".!text5"
Exception in Tkinter callback
Traceback (most recent call last):
  File "/Library/Frameworks/Python.framework/Versions/3.6/lib/python3.6/idlelib/run.py", line 137, in main
    seq, request = rpc.request_queue.get(block=True, timeout=0.05)
  File "/Library/Frameworks/Python.framework/Versions/3.6/lib/python3.6/queue.py", line 172, in get
    raise Empty
queue.Empty

During handling of the above exception, another exception occurred:

Traceback (most recent call last):
  File "/Library/Frameworks/Python.framework/Versions/3.6/lib/python3.6/tkinter/__init__.py", line 1699, in __call__
    return self.func(*args)
  File "/Users/thomas_petty24/Downloads/USER1/_System/_Core/Emulator/G2/EG1.gr", line 1405, in mousep
    mousetext.delete(0.0, END)
  File "/Library/Frameworks/Python.framework/Versions/3.6/lib/python3.6/tkinter/__init__.py", line 3133, in delete
    self.tk.call(self._w, 'delete', index1, index2)
_tkinter.TclError: invalid command name ".!text5"
Exception in Tkinter callback
Traceback (most recent call last):
  File "/Library/Frameworks/Python.framework/Versions/3.6/lib/python3.6/idlelib/run.py", line 137, in main
    seq, request = rpc.request_queue.get(block=True, timeout=0.05)
  File "/Library/Frameworks/Python.framework/Versions/3.6/lib/python3.6/queue.py", line 172, in get
    raise Empty
queue.Empty

During handling of the above exception, another exception occurred:

Traceback (most recent call last):
  File "/Library/Frameworks/Python.framework/Versions/3.6/lib/python3.6/tkinter/__init__.py", line 1699, in __call__
    return self.func(*args)
  File "/Users/thomas_petty24/Downloads/USER1/_System/_Core/Emulator/G2/EG1.gr", line 1405, in mousep
    mousetext.delete(0.0, END)
  File "/Library/Frameworks/Python.framework/Versions/3.6/lib/python3.6/tkinter/__init__.py", line 3133, in delete
    self.tk.call(self._w, 'delete', index1, index2)
_tkinter.TclError: invalid command name ".!text5"
Exception in Tkinter callback
Traceback (most recent call last):
  File "/Library/Frameworks/Python.framework/Versions/3.6/lib/python3.6/idlelib/run.py", line 137, in main
    seq, request = rpc.request_queue.get(block=True, timeout=0.05)
  File "/Library/Frameworks/Python.framework/Versions/3.6/lib/python3.6/queue.py", line 172, in get
    raise Empty
queue.Empty

During handling of the above exception, another exception occurred:

Traceback (most recent call last):
  File "/Library/Frameworks/Python.framework/Versions/3.6/lib/python3.6/tkinter/__init__.py", line 1699, in __call__
    return self.func(*args)
  File "/Users/thomas_petty24/Downloads/USER1/_System/_Core/Emulator/G2/EG1.gr", line 1405, in mousep
    mousetext.delete(0.0, END)
  File "/Library/Frameworks/Python.framework/Versions/3.6/lib/python3.6/tkinter/__init__.py", line 3133, in delete
    self.tk.call(self._w, 'delete', index1, index2)
_tkinter.TclError: invalid command name ".!text5"
Return
Return
Return
m
BackSpace
p
r
i
n
t
??
parenleft
??
quotedbl
h
e
l
o
??
??
quotedbl
??
parenright
Return
Return
Return
Exception in Tkinter callback
Traceback (most recent call last):
  File "/Library/Frameworks/Python.framework/Versions/3.6/lib/python3.6/idlelib/run.py", line 137, in main
    seq, request = rpc.request_queue.get(block=True, timeout=0.05)
  File "/Library/Frameworks/Python.framework/Versions/3.6/lib/python3.6/queue.py", line 172, in get
    raise Empty
queue.Empty

During handling of the above exception, another exception occurred:

Traceback (most recent call last):
  File "/Library/Frameworks/Python.framework/Versions/3.6/lib/python3.6/tkinter/__init__.py", line 1699, in __call__
    return self.func(*args)
  File "/Users/thomas_petty24/Downloads/USER1/_System/_Core/Emulator/G2/SOCK.gr", line 787, in check
    text.highlight_pattern('.', '.')
  File "/Users/thomas_petty24/Downloads/USER1/_System/_Core/Emulator/G2/SOCK.gr", line 33, in highlight_pattern
    self.mark_set("ms", index)
  File "/Library/Frameworks/Python.framework/Versions/3.6/lib/python3.6/tkinter/__init__.py", line 3278, in mark_set
    self.tk.call(self._w, 'mark', 'set', markName, index)
_tkinter.TclError: invalid command name ".!frame.!colourtext"
Exception in Tkinter callback
Traceback (most recent call last):
  File "/Library/Frameworks/Python.framework/Versions/3.6/lib/python3.6/idlelib/run.py", line 137, in main
    seq, request = rpc.request_queue.get(block=True, timeout=0.05)
  File "/Library/Frameworks/Python.framework/Versions/3.6/lib/python3.6/queue.py", line 172, in get
    raise Empty
queue.Empty

During handling of the above exception, another exception occurred:

Traceback (most recent call last):
  File "/Library/Frameworks/Python.framework/Versions/3.6/lib/python3.6/tkinter/__init__.py", line 1699, in __call__
    return self.func(*args)
  File "/Users/thomas_petty24/Downloads/USER1/_System/_Core/Emulator/G2/SOCK.gr", line 787, in check
    text.highlight_pattern('.', '.')
  File "/Users/thomas_petty24/Downloads/USER1/_System/_Core/Emulator/G2/SOCK.gr", line 28, in highlight_pattern
    self.update()
  File "/Library/Frameworks/Python.framework/Versions/3.6/lib/python3.6/tkinter/__init__.py", line 1171, in update
    self.tk.call('update')
_tkinter.TclError: can't invoke "update" command:  application has been destroyed
Exception in Tkinter callback
Traceback (most recent call last):
  File "/Library/Frameworks/Python.framework/Versions/3.6/lib/python3.6/idlelib/run.py", line 137, in main
    seq, request = rpc.request_queue.get(block=True, timeout=0.05)
  File "/Library/Frameworks/Python.framework/Versions/3.6/lib/python3.6/queue.py", line 172, in get
    raise Empty
queue.Empty

During handling of the above exception, another exception occurred:

Traceback (most recent call last):
  File "/Library/Frameworks/Python.framework/Versions/3.6/lib/python3.6/tkinter/__init__.py", line 1699, in __call__
    return self.func(*args)
  File "/Users/thomas_petty24/Downloads/USER1/_System/_Core/Emulator/G2/STORE.gr", line 760, in coco25
    httpbox.config(cursor='None', fg='white', selectbackground='white', selectforeground='white', insertbackground='white')
  File "/Library/Frameworks/Python.framework/Versions/3.6/lib/python3.6/tkinter/__init__.py", line 1479, in configure
    return self._configure('configure', cnf, kw)
  File "/Library/Frameworks/Python.framework/Versions/3.6/lib/python3.6/tkinter/__init__.py", line 1470, in _configure
    self.tk.call(_flatten((self._w, cmd)) + self._options(cnf))
_tkinter.TclError: bad cursor spec "None"
Exception in Tkinter callback
Traceback (most recent call last):
  File "/Library/Frameworks/Python.framework/Versions/3.6/lib/python3.6/idlelib/run.py", line 137, in main
    seq, request = rpc.request_queue.get(block=True, timeout=0.05)
  File "/Library/Frameworks/Python.framework/Versions/3.6/lib/python3.6/queue.py", line 172, in get
    raise Empty
queue.Empty

During handling of the above exception, another exception occurred:

Traceback (most recent call last):
  File "/Library/Frameworks/Python.framework/Versions/3.6/lib/python3.6/tkinter/__init__.py", line 1699, in __call__
    return self.func(*args)
  File "/Users/thomas_petty24/Downloads/USER1/_System/_Core/Emulator/G2/STORE.gr", line 760, in coco25
    httpbox.config(cursor='None', fg='white', selectbackground='white', selectforeground='white', insertbackground='white')
  File "/Library/Frameworks/Python.framework/Versions/3.6/lib/python3.6/tkinter/__init__.py", line 1479, in configure
    return self._configure('configure', cnf, kw)
  File "/Library/Frameworks/Python.framework/Versions/3.6/lib/python3.6/tkinter/__init__.py", line 1470, in _configure
    self.tk.call(_flatten((self._w, cmd)) + self._options(cnf))
_tkinter.TclError: bad cursor spec "None"
Exception in Tkinter callback
Traceback (most recent call last):
  File "/Library/Frameworks/Python.framework/Versions/3.6/lib/python3.6/idlelib/run.py", line 137, in main
    seq, request = rpc.request_queue.get(block=True, timeout=0.05)
  File "/Library/Frameworks/Python.framework/Versions/3.6/lib/python3.6/queue.py", line 172, in get
    raise Empty
queue.Empty

During handling of the above exception, another exception occurred:

Traceback (most recent call last):
  File "/Library/Frameworks/Python.framework/Versions/3.6/lib/python3.6/tkinter/__init__.py", line 1699, in __call__
    return self.func(*args)
  File "/Users/thomas_petty24/Downloads/USER1/_System/_Core/Emulator/G2/STORE.gr", line 760, in coco25
    httpbox.config(cursor='None', fg='white', selectbackground='white', selectforeground='white', insertbackground='white')
  File "/Library/Frameworks/Python.framework/Versions/3.6/lib/python3.6/tkinter/__init__.py", line 1479, in configure
    return self._configure('configure', cnf, kw)
  File "/Library/Frameworks/Python.framework/Versions/3.6/lib/python3.6/tkinter/__init__.py", line 1470, in _configure
    self.tk.call(_flatten((self._w, cmd)) + self._options(cnf))
_tkinter.TclError: bad cursor spec "None"
Exception in Tkinter callback
Traceback (most recent call last):
  File "/Library/Frameworks/Python.framework/Versions/3.6/lib/python3.6/idlelib/run.py", line 137, in main
    seq, request = rpc.request_queue.get(block=True, timeout=0.05)
  File "/Library/Frameworks/Python.framework/Versions/3.6/lib/python3.6/queue.py", line 172, in get
    raise Empty
queue.Empty

During handling of the above exception, another exception occurred:

Traceback (most recent call last):
  File "/Library/Frameworks/Python.framework/Versions/3.6/lib/python3.6/tkinter/__init__.py", line 1699, in __call__
    return self.func(*args)
  File "<string>", line 1, in <lambda>
  File "/Users/thomas_petty24/Downloads/USER1/_System/_Core/Emulator/G2/GVP.gr", line 33, in virusprotect
    gvp = Tk()
  File "/Library/Frameworks/Python.framework/Versions/3.6/lib/python3.6/tkinter/tix.py", line 214, in __init__
    self.tk.eval('package require Tix')
_tkinter.TclError: can't find package Tix
Traceback (most recent call last):
	
SyntaxError: invalid syntax
>>> 
>>> 
>>> 
>>> f = open("Documents/hash.txt", "r")
Traceback (most recent call last):
  File "<pyshell#4>", line 1, in <module>
    f = open("Documents/hash.txt", "r")
FileNotFoundError: [Errno 2] No such file or directory: 'Documents/hash.txt'
>>> f = open("hash.txt", "r")
Traceback (most recent call last):
  File "<pyshell#5>", line 1, in <module>
    f = open("hash.txt", "r")
FileNotFoundError: [Errno 2] No such file or directory: 'hash.txt'
>>> f = open("/Documents/hash.txt", "r")
Traceback (most recent call last):
  File "<pyshell#6>", line 1, in <module>
    f = open("/Documents/hash.txt", "r")
FileNotFoundError: [Errno 2] No such file or directory: '/Documents/hash.txt'
>>> f = open("hash.txt", "r")
Traceback (most recent call last):
  File "<pyshell#7>", line 1, in <module>
    f = open("hash.txt", "r")
FileNotFoundError: [Errno 2] No such file or directory: 'hash.txt'
>>> f = open("hash.txt", "a+")
>>> 
>>> print(str(f.read()))

>>> f.close()
>>> f = open("hash.txt", "r")
>>> f.read()
''
>>> f.read(5)
''
>>> f.write("hello")
Traceback (most recent call last):
  File "<pyshell#15>", line 1, in <module>
    f.write("hello")
io.UnsupportedOperation: not writable
>>> f.close()
>>> f = open("hash.txt", "a")
>>> f.read()
Traceback (most recent call last):
  File "<pyshell#18>", line 1, in <module>
    f.read()
io.UnsupportedOperation: not readable
>>> f.write("hello")
5
>>> f.read()
Traceback (most recent call last):
  File "<pyshell#20>", line 1, in <module>
    f.read()
io.UnsupportedOperation: not readable
>>> f.close()
>>> f = open("hash.txt", "r")
>>> f.read()
'hello'
>>> o = open("HASH.txt", "a")
>>> o.read()
Traceback (most recent call last):
  File "<pyshell#25>", line 1, in <module>
    o.read()
io.UnsupportedOperation: not readable
>>> o = open("HASH.txt", "r")
>>> o
<_io.TextIOWrapper name='HASH.txt' mode='r' encoding='US-ASCII'>
>>> o.read()
'hello'
>>> j = open("HASH_TEST.txt", "r")
Traceback (most recent call last):
  File "<pyshell#29>", line 1, in <module>
    j = open("HASH_TEST.txt", "r")
FileNotFoundError: [Errno 2] No such file or directory: 'HASH_TEST.txt'
>>> p = open("PY.txt", "a")
>>> p.read()
Traceback (most recent call last):
  File "<pyshell#31>", line 1, in <module>
    p.read()
io.UnsupportedOperation: not readable
>>> p = pen("PY.txt", "r")
Traceback (most recent call last):
  File "<pyshell#32>", line 1, in <module>
    p = pen("PY.txt", "r")
TypeError: pen() takes from 0 to 1 positional arguments but 2 were given
>>> p = open("PY.txt", "r")
>>> p.read()
''
>>> p = open("PY.txt", "w")
>>> p.write("hello")
5
>>> p.read()
Traceback (most recent call last):
  File "<pyshell#38>", line 1, in <module>
    p.read()
io.UnsupportedOperation: not readable
>>> p
<_io.TextIOWrapper name='PY.txt' mode='w' encoding='US-ASCII'>
>>> p = <_io.TextIOWrapper name='PY.txt' mode='w' encoding='UTF-8'>
SyntaxError: invalid syntax
>>> P = open("test.txt", "a", 'utf-8')
Traceback (most recent call last):
  File "<pyshell#41>", line 1, in <module>
    P = open("test.txt", "a", 'utf-8')
TypeError: an integer is required (got type str)
>>> p = '<_io.TextIOWrapper name='PY.txt' mode='w' encoding='UTF-8'>'
SyntaxError: invalid syntax
>>> p = "<_io.TextIOWrapper name='PY.txt' mode='w' encoding='UTF-8'>"
>>> p.write("hello")
Traceback (most recent call last):
  File "<pyshell#44>", line 1, in <module>
    p.write("hello")
AttributeError: 'str' object has no attribute 'write'
>>> h = open("test_copy.txt", "r")
Traceback (most recent call last):
  File "<pyshell#45>", line 1, in <module>
    h = open("test_copy.txt", "r")
FileNotFoundError: [Errno 2] No such file or directory: 'test_copy.txt'
>>> h = open("test_copy.txt", "r")
Traceback (most recent call last):
  File "<pyshell#46>", line 1, in <module>
    h = open("test_copy.txt", "r")
FileNotFoundError: [Errno 2] No such file or directory: 'test_copy.txt'
>>> import io
>>> from io import *
>>> f = open("test.txt", "r", encoding="utf-8")
Traceback (most recent call last):
  File "<pyshell#49>", line 1, in <module>
    f = open("test.txt", "r", encoding="utf-8")
FileNotFoundError: [Errno 2] No such file or directory: 'test.txt'
>>> f = open("test.txt", "r", encoding="utf-8")
Traceback (most recent call last):
  File "<pyshell#50>", line 1, in <module>
    f = open("test.txt", "r", encoding="utf-8")
FileNotFoundError: [Errno 2] No such file or directory: 'test.txt'
>>> f = open("test.txt", "w+", encoding="utf-8")
>>> f.write("hello")
5
>>> f = open("TE3T.txt", "w+", encoding="utf-8")
>>> f.write("hello")
5
>>> f = open("TE3T.txt", "r", encoding="utf-8")
>>> f.read()
'hello'
>>> FILE = open("hasher3.txt", "r", encoding="utf-8")
Traceback (most recent call last):
  File "<pyshell#57>", line 1, in <module>
    FILE = open("hasher3.txt", "r", encoding="utf-8")
FileNotFoundError: [Errno 2] No such file or directory: 'hasher3.txt'
>>> FILE = open("hasher35.txt", "w+", encoding="utf-8")
>>> FILE.write("hello")
5
>>> 
=========== RESTART: /Users/thomas_petty24/Documents/miner_good.py ===========
Traceback (most recent call last):
  File "/Users/thomas_petty24/Documents/miner_good.py", line 100, in <module>
    run()
  File "/Users/thomas_petty24/Documents/miner_good.py", line 70, in run
    FILE = open("hasher35.txt", "r", encoding="utf-8")
FileNotFoundError: [Errno 2] No such file or directory: 'hasher35.txt'
>>> 
=========== RESTART: /Users/thomas_petty24/Documents/miner_good.py ===========
Traceback (most recent call last):
  File "/Users/thomas_petty24/Documents/miner_good.py", line 100, in <module>
    run()
  File "/Users/thomas_petty24/Documents/miner_good.py", line 70, in run
    FILE = open("hasher35.txt", "r+", encoding="utf-8")
FileNotFoundError: [Errno 2] No such file or directory: 'hasher35.txt'
>>> 
=========== RESTART: /Users/thomas_petty24/Documents/miner_good.py ===========

dc5b695e2c0de57e3aa61c2946a1a8e2
>>> from MD2 import *
>>> MD2("bod2cody6")
'90449e435560fe980905a43c11004dd5'
>>> MD2("bob2cody\n")
'b80ba3b3966f44959b6a344fd5b641fa'
>>> MD2("bob2cody")
'0b16fa5f50395315925762ac5f3d5b5e'
>>> MD2("bob2cody6")
'9aa00cab04bfc9bfb8d81b4fe6d65e90'
>>> MD2()
Traceback (most recent call last):
  File "<pyshell#65>", line 1, in <module>
    MD2()
TypeError: MD2() missing 1 required positional argument: 'message'
>>> MD2("")
'dc5b695e2c0de57e3aa61c2946a1a8e2'
>>> MD2("The quick brown fox jumps over the lazy cog")
'159e1c7a3bae9c62787228feeabc242f'
>>> 
============== RESTART: /Users/thomas_petty24/Documents/MD4.py ==============
>>> from MD4 import *
>>> md5_hash("hello")
Traceback (most recent call last):
  File "<pyshell#69>", line 1, in <module>
    md5_hash("hello")
  File "/Users/thomas_petty24/Documents/MD4.py", line 24, in md5_hash
    file += b'\x80'
TypeError: must be str, not bytes
>>> md5_hash("hello")
Traceback (most recent call last):
  File "<pyshell#70>", line 1, in <module>
    md5_hash("hello")
  File "/Users/thomas_petty24/Documents/MD4.py", line 24, in md5_hash
    file += b'\x80'
TypeError: must be str, not bytes
>>> md5_hash("hello")
Traceback (most recent call last):
  File "<pyshell#71>", line 1, in <module>
    md5_hash("hello")
  File "/Users/thomas_petty24/Documents/MD4.py", line 24, in md5_hash
    if (len(file) % 64) != 56:
TypeError: must be str, not bytes
>>> md5_hash("hello")
Traceback (most recent call last):
  File "<pyshell#72>", line 1, in <module>
    md5_hash("hello")
  File "/Users/thomas_petty24/Documents/MD4.py", line 24, in md5_hash
    if (len(str(file)) % 64) != 56:
TypeError: must be str, not bytes
>>> from MD2 import *
>>> from MD4 import *
>>> md4_hash("hi")
Traceback (most recent call last):
  File "<pyshell#75>", line 1, in <module>
    md4_hash("hi")
NameError: name 'md4_hash' is not defined
>>> 
============== RESTART: /Users/thomas_petty24/Documents/MD4.py ==============
Traceback (most recent call last):
  File "/Users/thomas_petty24/Documents/MD4.py", line 139, in <module>
    md4_hash("hi")
  File "/Users/thomas_petty24/Documents/MD4.py", line 24, in md4_hash
    file += b'\x80'
TypeError: must be str, not bytes
>>> 
============== RESTART: /Users/thomas_petty24/Documents/MD4.py ==============
Traceback (most recent call last):
  File "/Users/thomas_petty24/Documents/MD4.py", line 139, in <module>
    md4_hash("hi")
  File "/Users/thomas_petty24/Documents/MD4.py", line 33, in md4_hash
    file += len64.ljust(8, b'\x00')
TypeError: must be str, not bytes
>>> 
=========== RESTART: /Users/thomas_petty24/Documents/miner_good.py ===========5
bob2cody6
Traceback (most recent call last):
  File "/Users/thomas_petty24/Documents/miner_good.py", line 108, in <module>
    run()
  File "/Users/thomas_petty24/Documents/miner_good.py", line 81, in run
    info = MD2(I)
  File "/Users/thomas_petty24/Documents/miner_good.py", line 13, in MD2
    i = bytearray(message)
NameError: name 'message' is not defined
>>> 
=========== RESTART: /Users/thomas_petty24/Documents/miner_good.py ===========
bob2cody6
Traceback (most recent call last):
  File "/Users/thomas_petty24/Documents/miner_good.py", line 108, in <module>
    run()
  File "/Users/thomas_petty24/Documents/miner_good.py", line 81, in run
    info = MD2(I)
  File "/Users/thomas_petty24/Documents/miner_good.py", line 13, in MD2
    i = bytearray(string)
TypeError: string argument without an encoding
>>> 
=========== RESTART: /Users/thomas_petty24/Documents/miner_good.py ===========
bob2cody6
Traceback (most recent call last):
  File "/Users/thomas_petty24/Documents/miner_good.py", line 108, in <module>
    run()
  File "/Users/thomas_petty24/Documents/miner_good.py", line 81, in run
    info = MD2(I)
  File "/Users/thomas_petty24/Documents/miner_good.py", line 14, in MD2
    h = MD2.new()
AttributeError: 'function' object has no attribute 'new'
>>> 
=========== RESTART: /Users/thomas_petty24/Documents/miner_good.py ===========
bob2cody6
None
Traceback (most recent call last):
  File "/Users/thomas_petty24/Documents/miner_good.py", line 108, in <module>
    run()
  File "/Users/thomas_petty24/Documents/miner_good.py", line 86, in run
    transfer_text.write(info)
TypeError: write() argument must be str, not None
>>> 
=========== RESTART: /Users/thomas_petty24/Documents/miner_good.py ===========
bob2cody6
None
>>> 
=========== RESTART: /Users/thomas_petty24/Documents/miner_good.py ===========
bob2cody6
None
>>> 
=========== RESTART: /Users/thomas_petty24/Documents/miner_good.py ===========
bob2cody6
db34cf0fc10a2dd3535e8931a71ae147
>>> 
======= RESTART: /Users/thomas_petty24/Desktop/MICROCOIN/miner_good.py =======
bob2cody6
db34cf0fc10a2dd3535e8931a71ae147
>>> 
======= RESTART: /Users/thomas_petty24/Desktop/MICROCOIN/miner_good.py =======
bob2cody6
db34cf0fc10a2dd3535e8931a71ae147
>>> 
